[[Информатика и программирование/23.05.26(Л)#Родовые классы]]
```cpp
#include <iostream>
using namespace std;

template <class X> class input
{
	X data;
public:
	input(char *s, X min, X max);
}

template <class X> input::input(char *s, X min, X max)
{
	do {
		cout << s << ":";
		cin >> data;
	} while (data < min || data > max)
}

int main()
{
	input <int> i("Enter integer\n", 0, 10);
	input <char> c("Enter character\n", 'a', 'n');
	return 0;
}
```

# Обработка исключений
`try` - `catch`
```cpp
try
{
	// контроллируемый блок
	throw выражение;
}
catch (type1 arg1)
{
	// блок перехвата
}
catch (type2 arg2) {}
// ...
catch (...) {} // универсальный блок
```

Универсальный блок перехватывает все ошибки.

`catch`
```cpp
catch (Type) {...}
catch (Type arg) {...}
catch (...) {...}
```

Можно вызывать `throw` внутри `catch`. Тогда исключение выходит на более высокий уровень.

```cpp
try{throw E;}
catch (H) {}
```
1. `H` и `E` одного типа.
2. `H` - открытый базовый класс для `E`.
3. `H` и `E` - указатели или ссылки и выполнено 1. или 2.

```cpp
#include <iostream>
using namespace std;

int main()
{
	cout << "Start\n";
	try
	{
		cout << "Entered try block\n";
		throw 10;
		cout << "Not printed\n";
	}
	catch(int i)
	{
		cout << "Got " << i << " throw\n";
	}
	cout << "End";
	return 0;
}
```

```cpp
#include <iostream>
using namespace std;

void SoftAbort()
{
	cerr << "Error";
	exit(1);
}

int main()
{
	set_terminate(SoftAbort);
	throw 5;
}
```

Работа с конструкторами/деструкторами
```cpp
#include <iostream>
using namespace std;

class A{
public:
	A(){cout << "Constructor\n";}
	~A(){cout << "Destructor\n";}
};

class Error{};
class ErrorOfA : public Error{};

void foo()
{
	A a;
	throw 1;
	cout<<"Foo\n";
}

int main()
{
	try
	{
		foo();
		throw ErrorOfA();
	}
	catch(int)
	{
		cout << "Int\n";
	}
	catch(ErrorOfAt)
	{
		cout << "ErrorOfA\n";
	}
	catch(Error)
	{
		cout << "Error\n";
	}
	return 0;
}
```

Классы исключений
```cpp
void Xhandler(int test)
{
	try
	{
		if(test==0)throw test;
		if(test==1)throw 'a';
		if(test==2)throw 12.23;
	}
	catch(int i){cout << "Throw " << i << endl;}
	catch(...){cout << "Error\n";}
}

int main()
{
	cout << "Start\n";
	Xhandler(0);
	Xhandler(1);
	Xhandler(2);
	Xhandler(23.23);
	return 0;
}
```

```cpp
void Func(int a) throw(Foo1, Foo2) {}
```
Функция может порождать исключения типов `Foo`, `Foo2`.
В случае, если случается исключение другого типа, вызывается `std::unexpected()`.
Задать `unexpected()` можно с помощью `set_unexpected(func_name)`.

Можно запретить генерировать исключения (`throw()`).

```cpp
void Xhandler() throw(int, char, double)
{
	try
	{
		throw "Hello\n";
	}
	catch(char *) {cout << "Throw char*\n"; throw;}
}

int main()
{
	try
	{
		Xhandler();
	}
	catch(char *) {cout << "Main char *" << endl;}
	return 0;
}
```

---
#theory #informatics_and_programming 